Workbook

Sheet UC people age
A1: Month | D1: December 2024 | E1: January 2025 | F1: February 2025 | G1: March 2025 | H1: April 2025 (rev) | I1: May 2025 (rev) | J1: June 2025 | K1: July 2025 | L1: August 2025 | M1: September 2025 | N1: October 2025 | O1: November 2025 | P1: December 2025 (r) | Q1: January 2026 (p)
B2: Age (bands and single year) (VI) | C2: Gender | S2: Death rates | T2: Expected monthly deaths
B3: 16-19 | C3: Male | D3: 81469 | E3: 80418 | F3: 81182 | G3: 82052 | H3: 82293 | I3: 80938 | J3: 79975 | K3: 79779 | L3: 81339 | M3: 82997 | N3: 87301 | O3: 90100 | P3: 90599 | Q3: 89609 | S3: 0.00027243332 | T3: =SUM(E3:P3)*S3/12 -> 22.679461
C4: Female | D4: 81761 | E4: 80695 | F4: 81260 | G4: 81668 | H4: 81537 | I4: 80084 | J4: 79319 | K4: 79745 | L4: 81355 | M4: 81760 | N4: 84784 | O4: 87068 | P4: 87643 | Q4: 86933 | S4: 0.00021110711 | T4: =SUM(E4:P4)*S4/12 -> 17.362117
B5: 20-24 | C5: Male | D5: 274520 | E5: 274353 | F5: 278476 | G5: 281154 | H5: 283167 | I5: 282333 | J5: 284303 | K5: 286016 | L5: 288846 | M5: 288305 | N5: 288632 | O5: 291366 | P5: 293251 | Q5: 297148 | S5: 0.00067303558 | T5: =SUM(E5:P5)*S5/12 -> 191.82647
C6: Female | D6: 308095 | E6: 306626 | F6: 308216 | G6: 308731 | H6: 309441 | I6: 308274 | J6: 309742 | K6: 311248 | L6: 313919 | M6: 313460 | N6: 313404 | O6: 315507 | P6: 316211 | Q6: 317843 | S6: 0.00033213698 | T6: =SUM(E6:P6)*S6/12 -> 103.37152
B7: 25-29 | C7: Male | D7: 302108 | E7: 302770 | F7: 306871 | G7: 309519 | H7: 311760 | I7: 311531 | J7: 313896 | K7: 318360 | L7: 324658 | M7: 330527 | N7: 334753 | O7: 337702 | P7: 339668 | Q7: 343338 | S7: 0.00087053675 | T7: =SUM(E7:P7)*S7/12 -> 278.71794
C8: Female | D8: 459042 | E8: 456816 | F8: 457775 | G8: 458278 | H8: 457890 | I8: 456964 | J8: 457524 | K8: 459427 | L8: 462314 | M8: 464639 | N8: 465446 | O8: 465828 | P8: 465965 | Q8: 466417 | S8: 0.00041706969 | T8: =SUM(E8:P8)*S8/12 -> 192.1602
B9: 30-34 | C9: Male | D9: 358346 | E9: 357767 | F9: 363273 | G9: 367464 | H9: 371598 | I9: 373704 | J9: 375710 | K9: 375838 | L9: 376849 | M9: 380518 | N9: 385316 | O9: 392673 | P9: 394931 | Q9: 398178 | S9: 0.0014259207 | T9: =SUM(E9:P9)*S9/12 -> 536.57882
C10: Female | D10: 628685 | E10: 627134 | F10: 630267 | G10: 631436 | H10: 632765 | I10: 632711 | J10: 632254 | K10: 630531 | L10: 629118 | M10: 629284 | N10: 629927 | O10: 630662 | P10: 630054 | Q10: 630376 | S10: 0.00073850005 | T10: =SUM(E10:P10)*S10/12 -> 465.63308
B11: 35-39 | C11: Male | D11: 404787 | E11: 407294 | F11: 415059 | G11: 420955 | H11: 426702 | I11: 428629 | J11: 430845 | K11: 432055 | L11: 433474 | M11: 435704 | N11: 439292 | O11: 445163 | P11: 447902 | Q11: 452119 | S11: 0.0022725565 | T11: =SUM(E11:P11)*S11/12 -> 977.78146
C12: Female | D12: 719132 | E12: 721395 | F12: 730438 | G12: 735439 | H12: 738977 | I12: 740378 | J12: 741997 | K12: 742780 | L12: 743200 | M12: 744357 | N12: 745199 | O12: 747733 | P12: 748953 | Q12: 750443 | S12: 0.0011509848 | T12: =SUM(E12:P12)*S12/12 -> 851.80993
B13: 40-44 | C13: Male | D13: 392668 | E13: 395138 | F13: 404921 | G13: 411592 | H13: 418710 | I13: 421546 | J13: 423992 | K13: 425094 | L13: 426292 | M13: 428383 | N13: 431303 | O13: 435721 | P13: 437768 | Q13: 440729 | S13: 0.0033775087 | T13: =SUM(E13:P13)*S13/12 -> 1424.3123
C14: Female | D14: 641911 | E14: 645671 | F14: 657081 | G14: 663026 | H14: 668594 | I14: 671443 | J14: 674776 | K14: 675801 | L14: 677434 | M14: 679471 | N14: 681874 | O14: 685050 | P14: 685855 | Q14: 688931 | S14: 0.0020452949 | T14: =SUM(E14:P14)*S14/12 -> 1374.792
B15: 45-49 | C15: Male | D15: 340329 | E15: 344961 | F15: 359185 | G15: 367664 | H15: 374339 | I15: 377629 | J15: 381493 | K15: 383284 | L15: 385461 | M15: 388091 | N15: 391324 | O15: 395741 | P15: 398123 | Q15: 400929 | S15: 0.0056359662 | T15: =SUM(E15:P15)*S15/12 -> 2135.7001
C16: Female | D16: 478376 | E16: 483630 | F16: 498612 | G16: 506863 | H16: 513434 | I16: 517377 | J16: 522350 | K16: 525067 | L16: 528671 | M16: 532125 | N16: 535787 | O16: 540277 | P16: 542662 | Q16: 546340 | S16: 0.002974891 | T16: =SUM(E16:P16)*S16/12 -> 1548.6427
B17: 50-54 | C17: Male | D17: 312455 | E17: 317336 | F17: 324493 | G17: 327186 | H17: 329460 | I17: 330723 | J17: 338283 | K17: 345266 | L17: 357979 | M17: 366577 | N17: 371471 | O17: 374619 | P17: 375331 | Q17: 376927 | S17: 0.0084624748 | T17: =SUM(E17:P17)*S17/12 -> 2932.7581
C18: Female | D18: 385572 | E18: 389180 | F18: 395496 | G18: 398456 | H18: 401004 | I18: 403204 | J18: 411236 | K18: 418662 | L18: 432342 | M18: 440642 | N18: 445249 | O18: 447974 | P18: 448390 | Q18: 450125 | S18: 0.0047924793 | T18: =SUM(E18:P18)*S18/12 -> 2009.5804
B19: 55-59 | C19: Male | D19: 273121 | E19: 276031 | F19: 280932 | G19: 283823 | H19: 290020 | I19: 299115 | J19: 316385 | K19: 333355 | L19: 346546 | M19: 351472 | N19: 356721 | O19: 362137 | P19: 365543 | Q19: 368701 | S19: 0.011592781 | T19: =SUM(E19:P19)*S19/12 -> 3731.0207
C20: Female | D20: 299923 | E20: 302061 | F20: 306491 | G20: 309488 | H20: 316828 | I20: 327861 | J20: 348586 | K20: 367226 | L20: 380857 | M20: 386228 | N20: 391828 | O20: 397725 | P20: 401398 | Q20: 404230 | S20: 0.0067480929 | T20: =SUM(E20:P20)*S20/12 -> 2382.4013
B21: 60-64 | C21: Male | D21: 232899 | E21: 235816 | F21: 240855 | G21: 247395 | H21: 255820 | I21: 264439 | J21: 280241 | K21: 286833 | L21: 296774 | M21: 304742 | N21: 316753 | O21: 328560 | P21: 333710 | Q21: 336926 | S21: 0.016812726 | T21: =SUM(E21:P21)*S21/12 -> 4752.3104
C22: Female | D22: 241393 | E22: 243745 | F22: 248037 | G22: 254955 | H22: 264376 | I22: 275022 | J22: 292862 | K22: 299530 | L22: 310942 | M22: 320881 | N22: 336101 | O22: 349645 | P22: 355097 | Q22: 357819 | S22: 0.010549005 | T22: =SUM(E22:P22)*S22/12 -> 3121.796
B23: 65-70 | C23: Male | D23: 76271 | E23: 78335 | F23: 80123 | G23: 81069 | H23: 82422 | I23: 83130 | J23: 84797 | K23: 86141 | L23: 88634 | M23: 91139 | N23: 95235 | O23: 97916 | P23: 99837 | Q23: 102213 | S23: 0.025778816 | T23: =SUM(E23:P23)*S23/12 -> 2253.0212
C24: Female | D24: 52164 | E24: 53368 | F24: 54335 | G24: 55031 | H24: 55954 | I24: 56707 | J24: 57782 | K24: 58656 | L24: 60655 | M24: 62935 | N24: 66803 | O24: 69726 | P24: 71523 | Q24: 74115 | S24: 0.017002508 | T24: =SUM(E24:P24)*S24/12 -> 1025.0741
B25: Over 70 (VI) | C25: Male | D25: 6562 | E25: 7293 | F25: 7882 | G25: 8158 | H25: 8526 | I25: 8826 | J25: 9169 | K25: 9493 | L25: 9857 | M25: 10052 | N25: 10349 | O25: 10625 | P25: 10555 | Q25: 10830 | S25: 0.077559491 | T25: =SUM(E25:P25)*S25/12 -> 716.03568
C26: Female | D26: 1694 | E26: 1934 | F26: 2121 | G26: 2203 | H26: 2311 | I26: 2370 | J26: 2497 | K26: 2564 | L26: 2674 | M26: 2728 | N26: 2787 | O26: 2746 | P26: 2529 | Q26: 2533 | S26: 0.065750682 | T26: =SUM(E26:P26)*S26/12 -> 161.43984
B27: Total | C27: Male | D27: 3055537 | E27: 3077507 | F27: 3143248 | G27: 3188023 | H27: 3234821 | I27: 3262540 | J27: 3319088 | K27: 3361515 | L27: 3416716 | M27: 3458509 | N27: 3508453 | O27: 3562322 | P27: 3587215 | Q27: 3617651 | T27: =SUM(T3+T5+T7+T9+T11+T13+T15+T17+T19+T21+T23+T25) -> 19952.743 | U27: Male deaths
C28: Female | D28: 4297756 | E28: 4312240 | F28: 4370120 | G28: 4405575 | H28: 4443118 | I28: 4472402 | J28: 4530917 | K28: 4571241 | L28: 4623476 | M28: 4658509 | N28: 4699192 | O28: 4739943 | P28: 4756267 | Q28: 4776110 | T28: =SUM(T4+T6+T8+T10+T12+T14+T16+T18+T20+T22+T24+T26) -> 13254.063 | U28: Female deaths
C30: Total | D30: =SUM(D27:D28) -> 7353293 | E30: =SUM(E27:E28) -> 7389747 | F30: =SUM(F27:F28) -> 7513368 | G30: =SUM(G27:G28) -> 7593598 | H30: =SUM(H27:H28) -> 7677939 | I30: =SUM(I27:I28) -> 7734942 | J30: =SUM(J27:J28) -> 7850005 | K30: =SUM(K27:K28) -> 7932756 | ... Q30: =SUM(Q27:Q28) -> 8393761 | T30: =T27+T28 -> 33206.806 | U30: Total deaths per month
C31: Starters | D31: 190528 | E31: 159620 | F31: 266800 | G31: 203355 | H31: 196686 | I31: 179104 | J31: 248960 | K31: 209263 | L31: 253398 | M31: 215843 | N31: 219807 | O31: 232719 | P31: 154924 | Q31: 102846
C32: Leavers | E32: =D30+E31-E30 -> 123166 | F32: =E30+F31-F30 -> 143179 | G32: =F30+G31-G30 -> 123125 | H32: =G30+H31-H30 -> 112345 | I32: =H30+I31-I30 -> 122101 | J32: =I30+J31-J30 -> 133897 | K32: =J30+K31-K30 -> 126512 | L32: =K30+L31-L30 -> 145962 | ... Q32: =P30+Q31-Q30 -> 52567
C33: Expected leavers due to pension | E33: 321.24081
C34: Expected leavers due to death | E34: =T30 -> 33206.806
C35: Expected leavers into work | E35: =E32-E33-E34 -> 89637.953 | F35: =F32-E33-E34 -> 109650.95 | G35: =G32-E33-E34 -> 89596.953 | H35: =H32-E33-E34 -> 78816.953 | I35: =I32-E33-E34 -> 88572.953 | J35: =J32-E33-E34 -> 100368.95 | K35: =K32-E33-E34 -> 92983.953 | L35: =L32-E33-E34 -> 112433.95 | M35: =M32-E33-E34 -> 105488.95 | N35: =N32-E33-E34 -> 95651.953 | O35: =O32-E33-E34 -> 104570.95 | P35: =P32-E33-E34 -> 80178.953
C37: Quarterly | D37: Q1 2025 | E37: =E35+F35+G35 -> 288885.86
D38: Q2 2025 | E38: =H35+I35+J35 -> 267758.86
D39: Q3 2025 | E39: =K35+L35+M35 -> 310906.86
D40: Q4 2025 | E40: =N35+O35+P35 -> 280401.86

Sheet UC people+starts age
A1: Month | C1: 45627 | D1: January 2025 | E1: February 2025 | F1: March 2025 | G1: April 2025 (rev) | H1: May 2025 (rev) | I1: June 2025 | J1: July 2025 | K1: August 2025 | L1: September 2025 | M1: October 2025 | N1: November 2025 | O1: December 2025 (r) | P1: January 2026 (p) | Q1: Total
B2: Employment indicator (V)
B3: Not in employment | C3: 4639662 | D3: 4730353 | E3: 4869313 | F3: 4924624 | G3: 5008017 | H3: 5077798 | I3: 5177927 | J3: 5261977 | K3: 5393526 | L3: 5476788 | M3: 5550590 | N3: 5619193 | O3: 5675966 | P3: ..
B4: In employment | C4: 2715818 | D4: 2661407 | E4: 2645768 | F4: 2670477 | G4: 2671436 | H4: 2658694 | I4: 2673559 | J4: 2671942 | K4: 2647601 | L4: 2640847 | M4: 2657223 | N4: 2683584 | O4: 2667690 | P4: ..
B5: Not available | D5: .. | E5: .. | F5: .. | G5: .. | H5: .. | I5: .. | J5: .. | K5: .. | L5: .. | M5: .. | N5: .. | O5: .. | P5: 8393940
B6: Total | C6: 7355479 | D6: 7391758 | E6: 7515081 | F6: 7595104 | G6: 7679452 | H6: 7736489 | I6: 7851487 | J6: 7933923 | K6: 8041126 | L6: 8117635 | M6: 8207815 | N6: 8302781 | O6: 8343654 | P6: 8393940
A7: Starts on Universal Credit | C7: 190528 | D7: 159620 | E7: 266800 | F7: 203355 | G7: 196686 | H7: 179104 | I7: 248960 | J7: 209263 | K7: 253398 | L7: 215843 | M7: 219807 | N7: 232719 | O7: 154924 | P7: 102846 | Q7: 2643331
B8: People carried over | C8: =C6-C7 -> 7164951 | D8: =D6-D7 -> 7232138 | E8: =E6-E7 -> 7248281 | F8: =F6-F7 -> 7391749 | G8: =G6-G7 -> 7482766 | H8: =H6-H7 -> 7557385 | I8: =I6-I7 -> 7602527 | J8: =J6-J7 -> 7724660 | ... P8: =P6-P7 -> 8291094
B9: Leavers | D9: =C6+D7-D6 -> 123341 | E9: =D6+E7-E6 -> 143477 | F9: =E6+F7-F6 -> 123332 | G9: =F6+G7-G6 -> 112338 | H9: =G6+H7-H6 -> 122067 | I9: =H6+I7-I6 -> 133962 | J9: =I6+J7-J6 -> 126827 | K9: =J6+K7-K6 -> 146195 | ... P9: =O6+P7-P6 -> 52560
B10: State Pension
B11: Death
B12: Under 65 | C12: =C6-C13-C14 -> 7218783 | D12: =D6-D13-D14 -> 7250833 | E12: =E6-E13-E14 -> 7370621 | F12: =F6-F13-F14 -> 7448641 | G12: =G6-G13-G14 -> 7530236 | H12: =H6-H13-H14 -> 7585452 | I12: =I6-I13-I14 -> 7697243 | J12: =J6-J13-J14 -> 7777075 | ... P12: =P6-P13-P14 -> 8204254
B13: 65-70 | C13: 128440 | D13: 131703 | E13: 134461 | F13: 136101 | G13: 138377 | H13: 139838 | I13: 142579 | J13: 144794 | K13: 149293 | L13: 154071 | M13: 162036 | N13: 167642 | O13: 171358 | P13: 176325
B14: 70+ | C14: 8256 | D14: 9222 | E14: 9999 | F14: 10362 | G14: 10839 | H14: 11199 | I14: 11665 | J14: 12054 | K14: 12533 | L14: 12778 | M14: 13140 | N14: 13372 | O14: 13082 | P14: 13361
A17: Pension effect | B17: Age (bands and single year) (VI)
B18: 60 | C18: 102967 | D18: 104384 | E18: 106145 | F18: 109083 | G18: 114750 | H18: 119607 | I18: 131103 | J18: 134330 | K18: 137118 | L18: 139067 | M18: 141892 | N18: 144230 | O18: 145609 | P18: 146301
B19: 61 | C19: 98010 | D19: 99108 | E19: 101154 | F19: 106165 | G19: 111624 | H19: 118041 | I19: 128337 | J19: 131896 | K19: 134518 | L19: 136767 | M19: 139317 | N19: 142134 | O19: 143979 | P19: 145425
B20: 62 | C20: 95328 | D20: 96270 | E20: 98017 | F20: 101411 | G20: 105607 | H20: 111393 | I20: 119943 | J20: 123942 | K20: 128789 | L20: 131591 | M20: 134104 | N20: 136739 | O20: 137787 | P20: 138719
B21: 63 | C21: 89601 | D21: 90745 | E21: 92939 | F21: 94509 | G21: 96003 | H21: 97395 | I21: 99534 | J21: 101131 | K21: 105737 | L21: 111315 | M21: 120576 | N21: 130539 | O21: 134375 | P21: 135539
B22: 64 | C22: 88383 | D22: 89060 | E22: 90635 | F22: 91183 | G22: 92221 | H22: 93023 | I22: 94191 | J22: 95065 | K22: 101552 | L22: 106891 | M22: 116958 | N22: 124568 | O22: 127050 | P22: 128766
B23: 65 | C23: 79280 | D23: 80593 | E23: 82713 | F23: 84434 | G23: 85816 | H23: 87033 | I23: 88973 | J23: 91025 | K23: 95582 | L23: 100256 | M23: 107352 | N23: 113000 | O23: 116735 | P23: 119660
B24: 66 | C24: 18437 | D24: 18674 | E24: 18130 | F24: 17711 | G24: 18120 | H24: 17973 | I24: 18071 | J24: 18172 | K24: 18541 | L24: 18752 | M24: 19337 | N24: 19181 | O24: 19310 | P24: 21097
B25: 67 | C25: 11912 | D25: 12631 | E25: 13041 | F25: 13136 | G25: 13219 | H25: 13192 | I25: 13301 | J25: 13063 | K25: 12579 | L25: 12332 | M25: 12277 | N25: 12348 | O25: 12324 | P25: 12317
B26: 68 | C26: 8163 | D26: 8552 | E26: 8879 | F26: 8968 | G26: 9155 | H26: 9323 | I26: 9580 | J26: 9652 | K26: 9619 | L26: 9647 | M26: 9758 | N26: 9746 | O26: 9693 | P26: 9834
B27: 69 | C27: 6193 | D27: 6411 | E27: 6557 | F27: 6657 | G27: 6794 | H27: 6936 | I27: 7092 | J27: 7227 | K27: 7264 | L27: 7338 | M27: 7510 | N27: 7606 | O27: 7543 | P27: 7679
B28: 70 | C28: 4464 | D28: 4837 | E28: 5136 | F28: 5185 | G28: 5274 | H28: 5384 | I28: 5571 | J28: 5662 | K28: 5706 | L28: 5747 | M28: 5800 | N28: 5760 | O28: 5750 | P28: 5740
B29: Over 70 (VI) | C29: 8256 | D29: 9222 | E29: 9999 | F29: 10362 | G29: 10839 | H29: 11199 | I29: 11665 | J29: 12054 | K29: 12533 | L29: 12778 | M29: 13140 | N29: 13372 | O29: 13082 | P29: 13361
B30: Total | C30: 610992 | D30: 620488 | E30: 633353 | F30: 648808 | G30: 669421 | H30: 690501 | I30: 727351 | J30: 743219 | K30: 769538 | L30: 792483 | M30: 828025 | N30: 859225 | O30: 873241 | P30: 884441
B31: Change 60 | D31: =D18-C18 -> 1417 | E31: =E18-D18 -> 1761 | F31: =F18-E18 -> 2938 | G31: =G18-F18 -> 5667 | H31: =H18-G18 -> 4857 | I31: =I18-H18 -> 11496 | J31: =J18-I18 -> 3227 | K31: =K18-J18 -> 2788 | ... P31: =P18-O18 -> 692
B32: Change 61 | D32: =D19-C19 -> 1098 | E32: =E19-D19 -> 2046 | F32: =F19-E19 -> 5011 | G32: =G19-F19 -> 5459 | H32: =H19-G19 -> 6417 | I32: =I19-H19 -> 10296 | J32: =J19-I19 -> 3559 | K32: =K19-J19 -> 2622 | ... P32: =P19-O19 -> 1446
B33: Change 62 | D33: =D20-C20 -> 942 | E33: =E20-D20 -> 1747 | F33: =F20-E20 -> 3394 | G33: =G20-F20 -> 4196 | H33: =H20-G20 -> 5786 | I33: =I20-H20 -> 8550 | J33: =J20-I20 -> 3999 | K33: =K20-J20 -> 4847 | ... P33: =P20-O20 -> 932
B34: Change 63 | D34: =D21-C21 -> 1144 | E34: =E21-D21 -> 2194 | F34: =F21-E21 -> 1570 | G34: =G21-F21 -> 1494 | H34: =H21-G21 -> 1392 | I34: =I21-H21 -> 2139 | J34: =J21-I21 -> 1597 | K34: =K21-J21 -> 4606 | ... P34: =P21-O21 -> 1164
B35: Change 64 | D35: =D22-C22 -> 677 | E35: =E22-D22 -> 1575 | F35: =F22-E22 -> 548 | G35: =G22-F22 -> 1038 | H35: =H22-G22 -> 802 | I35: =I22-H22 -> 1168 | J35: =J22-I22 -> 874 | K35: =K22-J22 -> 6487 | ... P35: =P22-O22 -> 1716
B36: Change 65 | D36: =D23-C23 -> 1313 | E36: =E23-D23 -> 2120 | F36: =F23-E23 -> 1721 | G36: =G23-F23 -> 1382 | H36: =H23-G23 -> 1217 | I36: =I23-H23 -> 1940 | J36: =J23-I23 -> 2052 | K36: =K23-J23 -> 4557 | ... P36: =P23-O23 -> 2925
B37: Change 66 | D37: =D24-C24 -> 237 | E37: =E24-D24 -> -544 | F37: =F24-E24 -> -419 | G37: =G24-F24 -> 409 | H37: =H24-G24 -> -147 | I37: =I24-H24 -> 98 | J37: =J24-I24 -> 101 | K37: =K24-J24 -> 369 | ... P37: =P24-O24 -> 1787
B38: Change 67 | D38: =D25-C25 -> 719 | E38: =E25-D25 -> 410 | F38: =F25-E25 -> 95 | G38: =G25-F25 -> 83 | H38: =H25-G25 -> -27 | I38: =I25-H25 -> 109 | J38: =J25-I25 -> -238 | K38: =K25-J25 -> -484 | ... P38: =P25-O25 -> -7
B39: Change 68 | D39: =D26-C26 -> 389 | E39: =E26-D26 -> 327 | F39: =F26-E26 -> 89 | G39: =G26-F26 -> 187 | H39: =H26-G26 -> 168 | I39: =I26-H26 -> 257 | J39: =J26-I26 -> 72 | K39: =K26-J26 -> -33 | ... P39: =P26-O26 -> 141
B40: Change 69 | D40: =D27-C27 -> 218 | E40: =E27-D27 -> 146 | F40: =F27-E27 -> 100 | G40: =G27-F27 -> 137 | H40: =H27-G27 -> 142 | I40: =I27-H27 -> 156 | J40: =J27-I27 -> 135 | K40: =K27-J27 -> 37 | ... P40: =P27-O27 -> 136
B41: Change 70 | D41: =D28-C28 -> 373 | E41: =E28-D28 -> 299 | F41: =F28-E28 -> 49 | G41: =G28-F28 -> 89 | H41: =H28-G28 -> 110 | I41: =I28-H28 -> 187 | J41: =J28-I28 -> 91 | K41: =K28-J28 -> 44 | ... P41: =P28-O28 -> -10 | T41: Growth in people moving to UC by age, showing the suppressive effect of the pension threshold
R42: Age | S42: Average monthly percentage change
...

Sheet Deaths decile 1
A1: Year | B1: Sex | C1: Age | D1: Decile | E1: Deaths | F1: Populations | G1: Rate
A2: 2024 | B2: males | C2: <1 | D2: 1 | E2: 285
A3: 2024 | B3: males | C3: <1 | D3: 2 | E3: 178
A4: 2024 | B4: males | C4: <1 | D4: 3 | E4: 186
A5: 2024 | B5: males | C5: <1 | D5: 4 | E5: 149
A6: 2024 | B6: males | C6: <1 | D6: 5 | E6: 117
A7: 2024 | B7: males | C7: <1 | D7: 6 | E7: 99
A8: 2024 | B8: males | C8: <1 | D8: 7 | E8: 117
A9: 2024 | B9: males | C9: <1 | D9: 8 | E9: 88
A10: 2024 | B10: males | C10: <1 | D10: 9 | E10: 79
A11: 2024 | B11: males | C11: <1 | D11: 10 | E11: 71
A12: 2024 | B12: males | C12: 01-04 | D12: 1 | E12: 40
A13: 2024 | B13: males | C13: 01-04 | D13: 2 | E13: 30
... A41: 2024 | B41: males | C41: 10-14 | D41: 10 | E41: 15
A42: 2024 | B42: males | C42: 15-19 | D42: 1 | E42: 61 | F42: ='Populations decile 1'!E42 -> 223908 | G42: =E42/F42 -> 0.00027243332
A43: 2024 | B43: males | C43: 15-19 | D43: 2 | E43: 91 | F43: 208425
A44: 2024 | B44: males | C44: 15-19 | D44: 3 | E44: 69 | F44: 213956
A45: 2024 | B45: males | C45: 15-19 | D45: 4 | E45: 63 | F45: 201724
A46: 2024 | B46: males | C46: 15-19 | D46: 5 | E46: 48 | F46: 214810
A47: 2024 | B47: males | C47: 15-19 | D47: 6 | E47: 50 | F47: 225382
A48: 2024 | B48: males | C48: 15-19 | D48: 7 | E48: 56 | F48: 218806
A49: 2024 | B49: males | C49: 15-19 | D49: 8 | E49: 47 | F49: 239675
A50: 2024 | B50: males | C50: 15-19 | D50: 9 | E50: 41 | F50: 212976
A51: 2024 | B51: males | C51: 15-19 | D51: 10 | E51: 43 | F51: 238057
A52: 2024 | B52: females | C52: 15-19 | D52: 1 | E52: 44 | F52: ='Populations decile 1'!E52 -> 208425 | G52: =E52/F52 -> 0.00021110711
A53: 2024 | B53: males | C53: 20-24 | D53: 2 | E53: 130 | F53: 207794
A54: 2024 | B54: males | C54: 20-24 | D54: 3 | E54: 101 | F54: 169270
A55: 2024 | B55: males | C55: 20-24 | D55: 4 | E55: 110 | F55: 171771
A56: 2024 | B56: males | C56: 20-24 | D56: 5 | E56: 74 | F56: 170872
A57: 2024 | B57: males | C57: 20-24 | D57: 6 | E57: 91 | F57: 173814
A58: 2024 | B58: males | C58: 20-24 | D58: 7 | E58: 70 | F58: 167173
A59: 2024 | B59: males | C59: 20-24 | D59: 8 | E59: 52 | F59: 169233
A60: 2024 | B60: males | C60: 20-24 | D60: 9 | E60: 48 | F60: 146972
A61: 2024 | B61: males | C61: 20-24 | D61: 10 | E61: 52 | F61: 148924
A62: 2024 | B62: males | C62: 20-24 | D62: 1 | E62: 144 | F62: ='Populations decile 1'!E62 -> 213956 | G62: =E62/F62 -> 0.00067303558
A63: 2024 | B63: males | C63: 25-29 | D63: 2 | E63: 145 | F63: 118806
A64: 2024 | B64: males | C64: 25-29 | D64: 3 | E64: 133 | F64: 88224
A65: 2024 | B65: males | C65: 25-29 | D65: 4 | E65: 124 | F65: 93690
A66: 2024 | B66: males | C66: 25-29 | D66: 5 | E66: 109 | F66: 66001
A67: 2024 | B67: males | C67: 25-29 | D67: 6 | E67: 102 | F67: 77938
...

Sheet Populations decile 1
A1: Year | B1: Sex | C1: Age | D1: Decile | E1: Populations
A2: 2024 | B2: males | C2: <1 | D2: 1 | E2: 39851
A3: 2024 | B3: males | C3: <1 | D3: 2 | E3: 35009
A4: 2024 | B4: males | C4: <1 | D4: 3 | E4: 33355
A5: 2024 | B5: males | C5: <1 | D5: 4 | E5: 30193
A6: 2024 | B6: males | C6: <1 | D6: 5 | E6: 28941
A7: 2024 | B7: males | C7: <1 | D7: 6 | E7: 27131
A8: 2024 | B8: males | C8: <1 | D8: 7 | E8: 26810
A9: 2024 | B9: males | C9: <1 | D9: 8 | E9: 26135
A10: 2024 | B10: males | C10: <1 | D10: 9 | E10: 25319
A11: 2024 | B11: males | C11: <1 | D11: 10 | E11: 21188
A12: 2024 | B12: males | C12: 01-04 | D12: 1 | E12: 170084
A13: 2024 | B13: males | C13: 01-04 | D13: 2 | E13: 147665
... A401: 2024 | B401: females | C401: 90+ | D401: 10 | E401: 43865

Sheet Sheet5
A1: Area | B1: Sex | C1: Age_band | D1: Population | E1: D1 population est | F1: Deaths
A2: England | B2: Male | C2: 15-19 | D2: 1807060 | E2: =D2/10 -> 180706 | F2: 223908
A3: England | B3: Female | C3: 15-19 | D3: 1702095 | E3: =D3/10 -> 170209.5 | F3: 208425
A4: England | B4: Male | C4: 20-24 | D4: 1807051 | E4: =D4/10 -> 180705.1 | F4: 213956
A5: England | B5: Female | C5: 20-24 | D5: 1718967 | E5: =D5/10 -> 171896.7 | F5: 201724
A6: England | B6: Male | C6: 25-29 | D6: 1927578 | E6: =D6/10 -> 192757.8 | F6: 214810
A7: England | B7: Female | C7: 25-29 | D7: 1957993 | E7: =D7/10 -> 195799.3 | F7: 225382
A8: England | B8: Male | C8: 30-34 | D8: 1994170 | E8: =D8/10 -> 199417 | F8: 218806
A9: England | B9: Female | C9: 30-34 | D9: 2106974 | E9: =D9/10 -> 210697.4 | F9: 239675
A10: England | B10: Male | C10: 35-39 | D10: 1962237 | E10: =D10/10 -> 196223.7 | F10: 212976
A11: England | B11: Female | C11: 35-39 | D11: 2111221 | E11: =D11/10 -> 211122.1 | F11: 238057
A12: England | B12: Male | C12: 40-44 | D12: 1868751 | E12: =D12/10 -> 186875.1 | F12: 194226
A13: England | B13: Female | C13: 40-44 | D13: 1986529 | E13: =D13/10 -> 198652.9 | F13: 207794
... A25: England | B25: Female | C25: 71+ | D25: 4141376 | E25: =D25/10 -> 414137.6 | F25: 273731

Sheet ACC Off-flows to Aug 22
A1: Benefit Group | D1: Jobseeker's Allowance | E1: Universal Credit Searching for Work | F1: Additionals | G1: Total
B2: Month of Off Flow | C2: Employment Indicator
B3: April 2021 | C3: Not in employment | D3: 32499 | E3: 148450 | F3: 8375 | G3: 189317
C4: In employment | D4: 4311 | E4: 133569 | F4: 2259 | G4: 140136
C5: Not available | D5: .. | E5: .. | F5: .. | G5: ..
C6: Total | D6: 36807 | E6: 282017 | F6: 10632 | G6: 329448
B7: May 2021 | C7: Not in employment | D7: 46134 | E7: 184412 | F7: 8217 | G7: 238757
C8: In employment | D8: 6597 | E8: 135236 | F8: 1468 | G8: 143296
C9: Not available | D9: .. | E9: .. | F9: .. | G9: ..
C10: Total | D10: 52728 | E10: 319647 | F10: 9685 | G10: 382057
B11: June 2021 | C11: Not in employment | D11: 25802 | E11: 233724 | F11: 7015 | G11: 266548
C12: In employment | D12: 3512 | E12: 175427 | F12: 1883 | G12: 180822
C13: Not available | D13: .. | E13: .. | F13: .. | G13: ..
C14: Total | D14: 29315 | E14: 409153 | F14: 8899 | G14: 447368
B15: July 2021 | C15: Not in employment | D15: 19117 | E15: 177904 | F15: 7421 | G15: 204437
C16: In employment | D16: 2806 | E16: 168108 | F16: 1882 | G16: 172803
C17: Not available | D17: .. | E17: .. | F17: .. | G17: ..
C18: Total | D18: 21927 | E18: 346015 | F18: 9308 | G18: 377243
B19: August 2021 | C19: Not in employment | D19: 17309 | E19: 160710 | F19: 9604 | G19: 187624
C20: In employment | D20: 2424 | E20: 130847 | F20: 2764 | G20: 136033
C21: Not available | D21: .. | E21: .. | F21: .. | G21: ..
C22: Total | D22: 19729 | E22: 291554 | F22: 12367 | G22: 323657
B23: September 2021 | C23: Not in employment | D23: 16670 | E23: 202953 | F23: 12762 | G23: 232385
C24: In employment | D24: 2436 | E24: 157517 | F24: 3202 | G24: 163159
C25: Not available | D25: .. | E25: .. | F25: .. | G25: ..
C26: Total | D26: 19107 | E26: 360471 | F26: 15965 | G26: 395541
B27: October 2021 | C27: Not in employment | D27: 15200 | E27: 176138 | F27: 7304 | G27: 198638
C28: In employment | D28: 2193 | E28: 127183 | F28: 1688 | G28: 131061
C29: Not available | D29: .. | E29: .. | F29: .. | G29: ..
C30: Total | D30: 17390 | E30: 303321 | F30: 8989 | G30: 329698
B31: November 2021 | C31: Not in employment | D31: 13113 | E31: 174248 | F31: 7603 | G31: 194962
C32: In employment | D32: 1833 | E32: 162310 | F32: 1607 | G32: 165751
C33: Not available | D33: .. | E33: .. | F33: .. | G33: ..
C34: Total | D34: 14945 | E34: 336556 | F34: 9206 | G34: 360709
B35: December 2021 | C35: Not in employment | D35: 12529 | E35: 165441 | F35: 12891 | G35: 190864
C36: In employment | D36: 1695 | E36: 158997 | F36: 1941 | G36: 162634
C37: Not available | D37: .. | E37: .. | F37: .. | G37: ..
C38: Total | D38: 14224 | E38: 324443 | F38: 14835 | G38: 353504
B39: January 2022 | C39: Not in employment | D39: 8050 | E39: 119145 | F39: 6335 | G39: 133534
C40: In employment | D40: 1140 | E40: 118648 | F40: 1167 | G40: 120956
...
